Workbook
Name COMPLETIONS: [1]Settings!$B$3
Name COMPLETIONS: [1]Settings!$B$3
Name COMPLETIONS: Settings!$B$3
Name DEF_0_PTS_ALLOW: Settings!$B$22
Name DEF_1_6_PTS_ALLOW: Settings!$B$23
Name DEF_14_21_PTS_ALLOW: Settings!$B$25
Name DEF_22_27_PTS_ALLOW: Settings!$B$26
Name DEF_28_35_PTS_ALLOW: Settings!$B$27
Name DEF_35__PTS_ALLOW: Settings!$B$28
Name DEF_7_13_PTS_ALLOW: Settings!$B$24
Name DEF_FORCE_FUMBLE: Settings!$B$18
Name DEF_INT: Settings!$B$17
Name DEF_RECOVER_FUMBLE: Settings!$B$19
Name DEF_SACKS: Settings!$B$16
Name DEF_SAFETIES: Settings!$B$20
Name DEF_TOUCHDOWN: Settings!$B$21
Name DEF_YD_ALLOW_PER: Settings!#REF!
Name FLEXVORPCalc: 'OVR & VORP Ranks'!$AD$6
Name INTERCEPTIONS: [1]Settings!$B$6
Name INTERCEPTIONS: [1]Settings!$B$6
Name INTERCEPTIONS: Settings!$B$6
Name PASS_ATTEMPTS: [1]Settings!$B$2
Name PASS_ATTEMPTS: [1]Settings!$B$2
Name PASS_ATTEMPTS: Settings!$B$2
Name PASS_TDS: [1]Settings!$B$5
Name PASS_TDS: [1]Settings!$B$5
Name PASS_TDS: Settings!$B$5
Name PASS_YARDS: [1]Settings!$B$4
Name PASS_YARDS: [1]Settings!$B$4
Name PASS_YARDS: Settings!$B$4
Name QBVORPCalc: 'OVR & VORP Ranks'!$AD$2
Name RBVORPCalc: 'OVR & VORP Ranks'!$AD$3
Name RECEPTIONS_RB: [1]Settings!$B$11
Name RECEPTIONS_RB: [1]Settings!$B$11
Name RECEPTIONS_RB: Settings!$B$11
Name RECEPTIONS_TE: [1]Settings!$B$13
Name RECEPTIONS_TE: [1]Settings!$B$13
Name RECEPTIONS_TE: Settings!$B$13
Name RECEPTIONS_WR: [1]Settings!$B$12
Name RECEPTIONS_WR: [1]Settings!$B$12
Name RECEPTIONS_WR: Settings!$B$12
Name RECV_TDS: [1]Settings!$B$15
Name RECV_TDS: [1]Settings!$B$15
Name RECV_TDS: Settings!$B$15
Name RECV_YARDS: [1]Settings!$B$14
Name RECV_YARDS: [1]Settings!$B$14
Name RECV_YARDS: Settings!$B$14
Name RUSH_ATTEMPTS: [1]Settings!$B$7
Name RUSH_ATTEMPTS: [1]Settings!$B$7
Name RUSH_ATTEMPTS: Settings!$B$7
Name RUSH_TDS: [1]Settings!$B$9
Name RUSH_TDS: [1]Settings!$B$9
Name RUSH_TDS: Settings!$B$9
Name RUSH_YARDS: [1]Settings!$B$8
Name RUSH_YARDS: [1]Settings!$B$8
Name RUSH_YARDS: Settings!$B$8
Name SFLEXVORPCalc: 'OVR & VORP Ranks'!$AD$7
Name STARTING_DST: Settings!$E$7
Name STARTING_FLEX: Settings!$E$9
Name STARTING_QB: Settings!$E$3

Sheet Instructions
A1: LINK TO THE SITE WITH STEP-BY-STEP DEEPER INSTRUCTIONS AND PICTURES
A3: OPEN IN EXCEL | B3: If you don't have Excel, you can access Office 365 online (just have to create an account if you don't have one), so…
B4: GO HERE to access Excel online and open the file
A5: CELLS | B5: There are cells all the way to the right, up to Column AH - make sure you see/use all of them if changing numbers
A6: STATS TO EDIT | B6: Only change stats in YELLOW - the rest will auto-calculate after you make changes
A7: STAT TOTALS | B7: Columns AE-AH should total 100% or less -- the calcuations will still adjust to 98% (Columns W, AA, AC), but it's forcing the numbers if you're over 100% and/or inflating them if way low
A8: POSITION DIFFERENCES | B8: QB attempt total can't be manipulated manually - you must change TEAM PLAYS, TEAM PASS% and/or QB PASS SHARE
A9: MORE TEAM STATS/TOTALS | B9: You can only edit PASS% (RUSH% auto adjusts to equal 100). Also, TEAM YPC and TD% affect "available" rushing yards and TDs -- QB YPA and PASS TD% affect "available" targets, receptions (yards and TDs)
A11: BENCHMARKS QB | B11: League average for TD% per COMP is around 7.1-7.2
A12: BENCHMARKS RB | B12: League average for TD% per RUSH ATT is around 3.8
A13: BENCHMARKS WR | B13: League average for TGT% is around 9.0
A14: BENCHMARKS TE | B14: League average for TGT% is around 5.5

Sheet Settings
A1: Category | B1: Points | D1: Category | E1: Value
A2: PASS ATTEMPTS | B2: 0 | D2: TEAMS | E2: 12
A3: COMPLETIONS | B3: 0.1 | D3: STARTING QB | E3: 1
A4: PASS YARDS | B4: 0.04 | D4: STARTING RB | E4: 2
A5: PASS TDS | B5: 6 | D5: STARTING WR | E5: 3
A6: INTERCEPTIONS | B6: -1 | D6: STARTING TE | E6: 1
A7: RUSH ATTEMPTS | B7: 0 | D7: STARTING DST | E7: 1
A8: RUSH YARDS | B8: 0.1 | D8: STARTING SUPERFLEX | E8: 1
A9: RUSH TDS | B9: 6 | D9: STARTING FLEX | E9: 1
A10: TARGETS | B10: 0 | D10: AUCTION BUDGET | E10: 200
A11: RECEPTIONS (RB) | B11: 0.5
A12: RECEPTIONS (WR) | B12: 0.5
A13: RECEPTIONS (TE) | B13: 0.5
A14: RECV YARDS | B14: 0.1
A15: RECV TDS | B15: 6
A16: DEF SACKS | B16: 1
A17: DEF INT | B17: 2
A18: DEF FORCE FUMBLE | B18: 1
A19: DEF RECOVER FUMBLE | B19: 2
A20: DEF SAFETIES | B20: 2
A21: DEF TOUCHDOWN | B21: 6
A22: DEF 0 PTS ALLOW | B22: 5
... A28: DEF 35+ PTS ALLOW | B28: -3

Sheet POS Ranks
A1: RK | B1: Player | C1: TM | D1: BYE | E1: FPS | F1: AUC$ | H1: RK | I1: Player | J1: TM | K1: BYE | L1: FPS | M1: AUC$ | O1: RK | P1: Player | Q1: TM | R1: BYE | S1: FPS | T1: AUC$ | V1: RK | W1: Player | X1: TM | Y1: BYE | Z1: FPS | AA1: AUC$ | AC1: RK | AD1: Player | AE1: BYE | AF1: FPS | AG1: AUC$
A2: 1 | B2: =IFERROR(INDEX(TableQBCalcPts[PLAYER],MATCH(TableQBRanks[[#This Row],[RK]],TableQBCalcPts[RK],0)),"") -> Josh Allen | C2: =IFERROR(INDEX(TableQBCalcPts[TM],MATCH(TableQBRanks[[#This Row],[RK]],TableQBCalcPts[RK],0)),"") -> BUF | D2: =IFERROR(INDEX(TableQBCalcPts[BYE],MATCH(TableQBRanks[[#This Row],[RK]],TableQBCalcPts[RK],0)),"") -> 7 | E2: =IFERROR(INDEX(TableQBCalcPts[Custom],MATCH(TableQBRanks[[#This Row],[RK]],TableQBCalcPts[RK],0)),"") -> 471.56584 | F2: =IF(VLOOKUP(TableQBRanks[[#This Row],[Player]],'Ranks w Proj'!$B:$N,13,FALSE)<0,0,VLOOKUP(TableQBRanks[[#This Row],[Player]],'Ranks w Proj'!$B:$N,13,FALSE)) -> 40.077402 | H2: 1 | I2: =IFERROR(INDEX(TableRBCalcPts[PLAYER],MATCH(TableRBRanks[[#This Row],[RK]],TableRBCalcPts[RK],0)),"") -> Jahmyr Gibbs | J2: =IFERROR(INDEX(TableRBCalcPts[TM],MATCH(TableRBRanks[[#This Row],[RK]],TableRBCalcPts[RK],0)),"") -> DET | K2: =IFERROR(INDEX(TableRBCalcPts[BYE],MATCH(TableRBRanks[[#This Row],[RK]],TableRBCalcPts[RK],0)),"") -> 6 | L2: =IFERROR(INDEX(TableRBCalcPts[Custom],MATCH(TableRBRanks[[#This Row],[RK]],TableRBCalcPts[RK],0)),"") -> 324.15018 | M2: =IF(VLOOKUP(TableRBRanks[[#This Row],[Player]],'Ranks w Proj'!$Q:$AB,12,FALSE)<0,0,VLOOKUP(TableRBRanks[[#This Row],[Player]],'Ranks w Proj'!$Q:$AB,12,FALSE)) -> 33.087955 | O2: 1 | P2: =IFERROR(INDEX(TableWRCalcPts[PLAYER],MATCH(TableWRRanks[[#This Row],[RK]],TableWRCalcPts[RK],0)),"") -> Jaxon Smith-Njigba | Q2: =IFERROR(INDEX(TableWRCalcPts[TM],MATCH(TableWRRanks[[#This Row],[RK]],TableWRCalcPts[RK],0)),"") -> SEA | R2: =IFERROR(INDEX(TableWRCalcPts[BYE],MATCH(TableWRRanks[[#This Row],[RK]],TableWRCalcPts[RK],0)),"") -> 11 | S2: =IFERROR(INDEX(TableWRCalcPts[Custom],MATCH(TableWRRanks[[#This Row],[RK]],TableWRCalcPts[RK],0)),"") -> 300.17511 | T2: =IF(VLOOKUP(TableWRRanks[[#This Row],[Player]],'Ranks w Proj'!$AE:$AO,11,FALSE)<0,0,VLOOKUP(TableWRRanks[[#This Row],[Player]],'Ranks w Proj'!$AE:$AO,11,FALSE)) -> 39.433926 | V2: 1 | W2: =IFERROR(INDEX(TableTECalcPts[PLAYER],MATCH(TableTERanks[[#This Row],[RK]],TableTECalcPts[RK],0)),"") -> Colston Loveland | X2: =IFERROR(INDEX(TableTECalcPts[TM],MATCH(TableTERanks[[#This Row],[RK]],TableTECalcPts[RK],0)),"") -> CHI | Y2: =IFERROR(INDEX(TableTECalcPts[BYE],MATCH(TableTERanks[[#This Row],[RK]],TableTECalcPts[RK],0)),"") -> 10 | Z2: =IFERROR(INDEX(TableTECalcPts[Custom],MATCH(TableTERanks[[#This Row],[RK]],TableTECalcPts[RK],0)),"") -> 193.51107 | AA2: =IF(VLOOKUP(TableTERanks[[#This Row],[Player]],'Ranks w Proj'!$AR:$AZ,9,FALSE)<0,0,VLOOKUP(TableTERanks[[#This Row],[Player]],'Ranks w Proj'!$AR:$AZ,9,FALSE)) -> 21.723467 | AC2: 1 | AD2: =IFERROR(INDEX(TableDSTCalcPts[PLAYER],MATCH(TableDSTRanks[[#This Row],[RK]],TableDSTCalcPts[RK],0)),"") -> Houston Texans | AE2: =IFERROR(INDEX(TableDSTCalcPts[BYE],MATCH(TableDSTRanks[[#This Row],[RK]],TableDSTCalcPts[RK],0)),"") -> 8 | AF2: =IFERROR(INDEX(TableDSTCalcPts[Custom],MATCH(TableDSTRanks[[#This Row],[RK]],TableDSTCalcPts[RK],0)),"") -> 147.00238 | AG2: 2
A3: 2 | B3: =IFERROR(INDEX(TableQBCalcPts[PLAYER],MATCH(TableQBRanks[[#This Row],[RK]],TableQBCalcPts[RK],0)),"") -> Joe Burrow | C3: =IFERROR(INDEX(TableQBCalcPts[TM],MATCH(TableQBRanks[[#This Row],[RK]],TableQBCalcPts[RK],0)),"") -> CIN | D3: =IFERROR(INDEX(TableQBCalcPts[BYE],MATCH(TableQBRanks[[#This Row],[RK]],TableQBCalcPts[RK],0)),"") -> 6 | E3: =IFERROR(INDEX(TableQBCalcPts[Custom],MATCH(TableQBRanks[[#This Row],[RK]],TableQBCalcPts[RK],0)),"") -> 448.82705 | F3: =IF(VLOOKUP(TableQBRanks[[#This Row],[Player]],'Ranks w Proj'!$B:$N,13,FALSE)<0,0,VLOOKUP(TableQBRanks[[#This Row],[Player]],'Ranks w Proj'!$B:$N,13,FALSE)) -> 35.720993 | H3: 2 | I3: =IFERROR(INDEX(TableRBCalcPts[PLAYER],MATCH(TableRBRanks[[#This Row],[RK]],TableRBCalcPts[RK],0)),"") -> Bijan Robinson | J3: =IFERROR(INDEX(TableRBCalcPts[TM],MATCH(TableRBRanks[[#This Row],[RK]],TableRBCalcPts[RK],0)),"") -> ATL | K3: =IFERROR(INDEX(TableRBCalcPts[BYE],MATCH(TableRBRanks[[#This Row],[RK]],TableRBCalcPts[RK],0)),"") -> 11 | L3: =IFERROR(INDEX(TableRBCalcPts[Custom],MATCH(TableRBRanks[[#This Row],[RK]],TableRBCalcPts[RK],0)),"") -> 322.904 | M3: =IF(VLOOKUP(TableRBRanks[[#This Row],[Player]],'Ranks w Proj'!$Q:$AB,12,FALSE)<0,0,VLOOKUP(TableRBRanks[[#This Row],[Player]],'Ranks w Proj'!$Q:$AB,12,FALSE)) -> 32.900652 | O3: 2 | P3: =IFERROR(INDEX(TableWRCalcPts[PLAYER],MATCH(TableWRRanks[[#This Row],[RK]],TableWRCalcPts[RK],0)),"") -> Ja'Marr Chase | Q3: =IFERROR(INDEX(TableWRCalcPts[TM],MATCH(TableWRRanks[[#This Row],[RK]],TableWRCalcPts[RK],0)),"") -> CIN | R3: =IFERROR(INDEX(TableWRCalcPts[BYE],MATCH(TableWRRanks[[#This Row],[RK]],TableWRCalcPts[RK],0)),"") -> 6 | S3: =IFERROR(INDEX(TableWRCalcPts[Custom],MATCH(TableWRRanks[[#This Row],[RK]],TableWRCalcPts[RK],0)),"") -> 298.87383 | T3: =IF(VLOOKUP(TableWRRanks[[#This Row],[Player]],'Ranks w Proj'!$AE:$AO,11,FALSE)<0,0,VLOOKUP(TableWRRanks[[#This Row],[Player]],'Ranks w Proj'!$AE:$AO,11,FALSE)) -> 39.189445 | V3: 2 | W3: =IFERROR(INDEX(TableTECalcPts[PLAYER],MATCH(TableTERanks[[#This Row],[RK]],TableTECalcPts[RK],0)),"") -> Brock Bowers | X3: =IFERROR(INDEX(TableTECalcPts[TM],MATCH(TableTERanks[[#This Row],[RK]],TableTECalcPts[RK],0)),"") -> LV | Y3: =IFERROR(INDEX(TableTECalcPts[BYE],MATCH(TableTERanks[[#This Row],[RK]],TableTECalcPts[RK],0)),"") -> 13 | Z3: =IFERROR(INDEX(TableTECalcPts[Custom],MATCH(TableTERanks[[#This Row],[RK]],TableTECalcPts[RK],0)),"") -> 189.2298 | AA3: =IF(VLOOKUP(TableTERanks[[#This Row],[Player]],'Ranks w Proj'!$AR:$AZ,9,FALSE)<0,0,VLOOKUP(TableTERanks[[#This Row],[Player]],'Ranks w Proj'!$AR:$AZ,9,FALSE)) -> 20.91911 | AC3: 2 | AD3: =IFERROR(INDEX(TableDSTCalcPts[PLAYER],MATCH(TableDSTRanks[[#This Row],[RK]],TableDSTCalcPts[RK],0)),"") -> Seattle Seahawks | AE3: =IFERROR(INDEX(TableDSTCalcPts[BYE],MATCH(TableDSTRanks[[#This Row],[RK]],TableDSTCalcPts[RK],0)),"") -> 11 | AF3: =IFERROR(INDEX(TableDSTCalcPts[Custom],MATCH(TableDSTRanks[[#This Row],[RK]],TableDSTCalcPts[RK],0)),"") -> 142.73571 | AG3: 2
A4: 3 | B4: =IFERROR(INDEX(TableQBCalcPts[PLAYER],MATCH(TableQBRanks[[#This Row],[RK]],TableQBCalcPts[RK],0)),"") -> Drake Maye | C4: =IFERROR(INDEX(TableQBCalcPts[TM],MATCH(TableQBRanks[[#This Row],[RK]],TableQBCalcPts[RK],0)),"") -> NE | D4: =IFERROR(INDEX(TableQBCalcPts[BYE],MATCH(TableQBRanks[[#This Row],[RK]],TableQBCalcPts[RK],0)),"") -> 11 | E4: =IFERROR(INDEX(TableQBCalcPts[Custom],MATCH(TableQBRanks[[#This Row],[RK]],TableQBCalcPts[RK],0)),"") -> 445.96284 | F4: =IF(VLOOKUP(TableQBRanks[[#This Row],[Player]],'Ranks w Proj'!$B:$N,13,FALSE)<0,0,VLOOKUP(TableQBRanks[[#This Row],[Player]],'Ranks w Proj'!$B:$N,13,FALSE)) -> 34.159683 | H4: 3 | I4: =IFERROR(INDEX(TableRBCalcPts[PLAYER],MATCH(TableRBRanks[[#This Row],[RK]],TableRBCalcPts[RK],0)),"") -> Christian McCaffrey | J4: =IFERROR(INDEX(TableRBCalcPts[TM],MATCH(TableRBRanks[[#This Row],[RK]],TableRBCalcPts[RK],0)),"") -> SF | K4: =IFERROR(INDEX(TableRBCalcPts[BYE],MATCH(TableRBRanks[[#This Row],[RK]],TableRBCalcPts[RK],0)),"") -> 8 | L4: =IFERROR(INDEX(TableRBCalcPts[Custom],MATCH(TableRBRanks[[#This Row],[RK]],TableRBCalcPts[RK],0)),"") -> 307.7762 | M4: =IF(VLOOKUP(TableRBRanks[[#This Row],[Player]],'Ranks w Proj'!$Q:$AB,12,FALSE)<0,0,VLOOKUP(TableRBRanks[[#This Row],[Player]],'Ranks w Proj'!$Q:$AB,12,FALSE)) -> 30.626904 | O4: 3 | P4: =IFERROR(INDEX(TableWRCalcPts[PLAYER],MATCH(TableWRRanks[[#This Row],[RK]],TableWRCalcPts[RK],0)),"") -> Puka Nacua | Q4: =IFERROR(INDEX(TableWRCalcPts[TM],MATCH(TableWRRanks[[#This Row],[RK]],TableWRCalcPts[RK],0)),"") -> LAR | R4: =IFERROR(INDEX(TableWRCalcPts[BYE],MATCH(TableWRRanks[[#This Row],[RK]],TableWRCalcPts[RK],0)),"") -> 11 | S4: =IFERROR(INDEX(TableWRCalcPts[Custom],MATCH(TableWRRanks[[#This Row],[RK]],TableWRCalcPts[RK],0)),"") -> 288.94555 | T4: =IF(VLOOKUP(TableWRRanks[[#This Row],[Player]],'Ranks w Proj'!$AE:$AO,11,FALSE)<0,0,VLOOKUP(TableWRRanks[[#This Row],[Player]],'Ranks w Proj'!$AE:$AO,11,FALSE)) -> 37.324137 | V4: 3 | W4: =IFERROR(INDEX(TableTECalcPts[PLAYER],MATCH(TableTERanks[[#This Row],[RK]],TableTECalcPts[RK],0)),"") -> Trey McBride | X4: =IFERROR(INDEX(TableTECalcPts[TM],MATCH(TableTERanks[[#This Row],[RK]],TableTECalcPts[RK],0)),"") -> ARI | Y4: =IFERROR(INDEX(TableTECalcPts[BYE],MATCH(TableTERanks[[#This Row],[RK]],TableTECalcPts[RK],0)),"") -> 14 | Z4: =IFERROR(INDEX(TableTECalcPts[Custom],MATCH(TableTERanks[[#This Row],[RK]],TableTECalcPts[RK],0)),"") -> 183.17819 | AA4: =IF(VLOOKUP(TableTERanks[[#This Row],[Player]],'Ranks w Proj'!$AR:$AZ,9,FALSE)<0,0,VLOOKUP(TableTERanks[[#This Row],[Player]],'Ranks w Proj'!$AR:$AZ,9,FALSE)) -> 19.782144 | AC4: 3 | AD4: =IFERROR(INDEX(TableDSTCalcPts[PLAYER],MATCH(TableDSTRanks[[#This Row],[RK]],TableDSTCalcPts[RK],0)),"") -> Denver Broncos | AE4: =IFERROR(INDEX(TableDSTCalcPts[BYE],MATCH(TableDSTRanks[[#This Row],[RK]],TableDSTCalcPts[RK],0)),"") -> 10 | AF4: =IFERROR(INDEX(TableDSTCalcPts[Custom],MATCH(TableDSTRanks[[#This Row],[RK]],TableDSTCalcPts[RK],0)),"") -> 140.82143 | AG4: 1
A5: 4 | B5: =IFERROR(INDEX(TableQBCalcPts[PLAYER],MATCH(TableQBRanks[[#This Row],[RK]],TableQBCalcPts[RK],0)),"") -> Lamar Jackson | C5: =IFERROR(INDEX(TableQBCalcPts[TM],MATCH(TableQBRanks[[#This Row],[RK]],TableQBCalcPts[RK],0)),"") -> BAL | D5: =IFERROR(INDEX(TableQBCalcPts[BYE],MATCH(TableQBRanks[[#This Row],[RK]],TableQBCalcPts[RK],0)),"") -> 13 | E5: =IFERROR(INDEX(TableQBCalcPts[Custom],MATCH(TableQBRanks[[#This Row],[RK]],TableQBCalcPts[RK],0)),"") -> 425.38039 | F5: =IF(VLOOKUP(TableQBRanks[[#This Row],[Player]],'Ranks w Proj'!$B:$N,13,FALSE)<0,0,VLOOKUP(TableQBRanks[[#This Row],[Player]],'Ranks w Proj'!$B:$N,13,FALSE)) -> 28.94425 | H5: 4 | I5: =IFERROR(INDEX(TableRBCalcPts[PLAYER],MATCH(TableRBRanks[[#This Row],[RK]],TableRBCalcPts[RK],0)),"") -> Jonathan Taylor | J5: =IFERROR(INDEX(TableRBCalcPts[TM],MATCH(TableRBRanks[[#This Row],[RK]],TableRBCalcPts[RK],0)),"") -> IND | K5: =IFERROR(INDEX(TableRBCalcPts[BYE],MATCH(TableRBRanks[[#This Row],[RK]],TableRBCalcPts[RK],0)),"") -> 13 | L5: =IFERROR(INDEX(TableRBCalcPts[Custom],MATCH(TableRBRanks[[#This Row],[RK]],TableRBCalcPts[RK],0)),"") -> 287.83953 | M5: =IF(VLOOKUP(TableRBRanks[[#This Row],[Player]],'Ranks w Proj'!$Q:$AB,12,FALSE)<0,0,VLOOKUP(TableRBRanks[[#This Row],[Player]],'Ranks w Proj'!$Q:$AB,12,FALSE)) -> 27.630372 | O5: 4 | P5: =IFERROR(INDEX(TableWRCalcPts[PLAYER],MATCH(TableWRRanks[[#This Row],[RK]],TableWRCalcPts[RK],0)),"") -> Amon-Ra St. Brown | Q5: =IFERROR(INDEX(TableWRCalcPts[TM],MATCH(TableWRRanks[[#This Row],[RK]],TableWRCalcPts[RK],0)),"") -> DET | R5: =IFERROR(INDEX(TableWRCalcPts[BYE],MATCH(TableWRRanks[[#This Row],[RK]],TableWRCalcPts[RK],0)),"") -> 6 | S5: =IFERROR(INDEX(TableWRCalcPts[Custom],MATCH(TableWRRanks[[#This Row],[RK]],TableWRCalcPts[RK],0)),"") -> 263.19538 | T5: =IF(VLOOKUP(TableWRRanks[[#This Row],[Player]],'Ranks w Proj'!$AE:$AO,11,FALSE)<0,0,VLOOKUP(TableWRRanks[[#This Row],[Player]],'Ranks w Proj'!$AE:$AO,11,FALSE)) -> 32.486242 | V5: 4 | W5: =IFERROR(INDEX(TableTECalcPts[PLAYER],MATCH(TableTERanks[[#This Row],[RK]],TableTECalcPts[RK],0)),"") -> Tyler Warren | X5: =IFERROR(INDEX(TableTECalcPts[TM],MATCH(TableTERanks[[#This Row],[RK]],TableTECalcPts[RK],0)),"") -> IND | Y5: =IFERROR(INDEX(TableTECalcPts[BYE],MATCH(TableTERanks[[#This Row],[RK]],TableTECalcPts[RK],0)),"") -> 13 | Z5: =IFERROR(INDEX(TableTECalcPts[Custom],MATCH(TableTERanks[[#This Row],[RK]],TableTECalcPts[RK],0)),"") -> 168.31978 | AA5: =IF(VLOOKUP(TableTERanks[[#This Row],[Player]],'Ranks w Proj'!$AR:$AZ,9,FALSE)<0,0,VLOOKUP(TableTERanks[[#This Row],[Player]],'Ranks w Proj'!$AR:$AZ,9,FALSE)) -> 16.990573 | AC5: 4 | AD5: =IFERROR(INDEX(TableDSTCalcPts[PLAYER],MATCH(TableDSTRanks[[#This Row],[RK]],TableDSTCalcPts[RK],0)),"") -> Los Angeles Rams | AE5: =IFERROR(INDEX(TableDSTCalcPts[BYE],MATCH(TableDSTRanks[[#This Row],[RK]],TableDSTCalcPts[RK],0)),"") -> 11 | AF5: =IFERROR(INDEX(TableDSTCalcPts[Custom],MATCH(TableDSTRanks[[#This Row],[RK]],TableDSTCalcPts[RK],0)),"") -> 138.2119 | AG5: 1
A6: 5 | B6: =IFERROR(INDEX(TableQBCalcPts[PLAYER],MATCH(TableQBRanks[[#This Row],[RK]],TableQBCalcPts[RK],0)),"") -> Dak Prescott | C6: =IFERROR(INDEX(TableQBCalcPts[TM],MATCH(TableQBRanks[[#This Row],[RK]],TableQBCalcPts[RK],0)),"") -> DAL | D6: =IFERROR(INDEX(TableQBCalcPts[BYE],MATCH(TableQBRanks[[#This Row],[RK]],TableQBCalcPts[RK],0)),"") -> 14 | E6: =IFERROR(INDEX(TableQBCalcPts[Custom],MATCH(TableQBRanks[[#This Row],[RK]],TableQBCalcPts[RK],0)),"") -> 424.26157 | F6: =IF(VLOOKUP(TableQBRanks[[#This Row],[Player]],'Ranks w Proj'!$B:$N,13,FALSE)<0,0,VLOOKUP(TableQBRanks[[#This Row],[Player]],'Ranks w Proj'!$B:$N,13,FALSE)) -> 26.377588 | H6: 5 | I6: =IFERROR(INDEX(TableRBCalcPts[PLAYER],MATCH(TableRBRanks[[#This Row],[RK]],TableRBCalcPts[RK],0)),"") -> James Cook | J6: =IFERROR(INDEX(TableRBCalcPts[TM],MATCH(TableRBRanks[[#This Row],[RK]],TableRBCalcPts[RK],0)),"") -> BUF | K6: =IFERROR(INDEX(TableRBCalcPts[BYE],MATCH(TableRBRanks[[#This Row],[RK]],TableRBCalcPts[RK],0)),"") -> 7 | L6: =IFERROR(INDEX(TableRBCalcPts[Custom],MATCH(TableRBRanks[[#This Row],[RK]],TableRBCalcPts[RK],0)),"") -> 252.99927 | M6: =IF(VLOOKUP(TableRBRanks[[#This Row],[Player]],'Ranks w Proj'!$Q:$AB,12,FALSE)<0,0,VLOOKUP(TableRBRanks[[#This Row],[Player]],'Ranks w Proj'!$Q:$AB,12,FALSE)) -> 22.393792 | O6: 5 | P6: =IFERROR(INDEX(TableWRCalcPts[PLAYER],MATCH(TableWRRanks[[#This Row],[RK]],TableWRCalcPts[RK],0)),"") -> George Pickens | Q6: =IFERROR(INDEX(TableWRCalcPts[TM],MATCH(TableWRRanks[[#This Row],[RK]],TableWRCalcPts[RK],0)),"") -> DAL | R6: =IFERROR(INDEX(TableWRCalcPts[BYE],MATCH(TableWRRanks[[#This Row],[RK]],TableWRCalcPts[RK],0)),"") -> 14 | S6: =IFERROR(INDEX(TableWRCalcPts[Custom],MATCH(TableWRRanks[[#This Row],[RK]],TableWRCalcPts[RK],0)),"") -> 232.51214 | T6: =IF(VLOOKUP(TableWRRanks[[#This Row],[Player]],'Ranks w Proj'!$AE:$AO,11,FALSE)<0,0,VLOOKUP(TableWRRanks[[#This Row],[Player]],'Ranks w Proj'!$AE:$AO,11,FALSE)) -> 26.72153 | V6: 5 | W6: =IFERROR(INDEX(TableTECalcPts[PLAYER],MATCH(TableTERanks[[#This Row],[RK]],TableTECalcPts[RK],0)),"") -> Sam LaPorta | X6: =IFERROR(INDEX(TableTECalcPts[TM],MATCH(TableTERanks[[#This Row],[RK]],TableTECalcPts[RK],0)),"") -> DET | Y6: =IFERROR(INDEX(TableTECalcPts[BYE],MATCH(TableTERanks[[#This Row],[RK]],TableTECalcPts[RK],0)),"") -> 6 | Z6: =IFERROR(INDEX(TableTECalcPts[Custom],MATCH(TableTERanks[[#This Row],[RK]],TableTECalcPts[RK],0)),"") -> 155.89637 | AA6: =IF(VLOOKUP(TableTERanks[[#This Row],[Player]],'Ranks w Proj'!$AR:$AZ,9,FALSE)<0,0,VLOOKUP(TableTERanks[[#This Row],[Player]],'Ranks w Proj'!$AR:$AZ,9,FALSE)) -> 14.656485 | AC6: 5 | AD6: =IFERROR(INDEX(TableDSTCalcPts[PLAYER],MATCH(TableDSTRanks[[#This Row],[RK]],TableDSTCalcPts[RK],0)),"") -> Pittsburgh Steelers | AE6: =IFERROR(INDEX(TableDSTCalcPts[BYE],MATCH(TableDSTRanks[[#This Row],[RK]],TableDSTCalcPts[RK],0)),"") -> 9 | AF6: =IFERROR(INDEX(TableDSTCalcPts[Custom],MATCH(TableDSTRanks[[#This Row],[RK]],TableDSTCalcPts[RK],0)),"") -> 137.51429 | AG6: 1
A7: 6 | B7: =IFERROR(INDEX(TableQBCalcPts[PLAYER],MATCH(TableQBRanks[[#This Row],[RK]],TableQBCalcPts[RK],0)),"") -> Brock Purdy | C7: =IFERROR(INDEX(TableQBCalcPts[TM],MATCH(TableQBRanks[[#This Row],[RK]],TableQBCalcPts[RK],0)),"") -> SF | D7: =IFERROR(INDEX(TableQBCalcPts[BYE],MATCH(TableQBRanks[[#This Row],[RK]],TableQBCalcPts[RK],0)),"") -> 8 | E7: =IFERROR(INDEX(TableQBCalcPts[Custom],MATCH(TableQBRanks[[#This Row],[RK]],TableQBCalcPts[RK],0)),"") -> 421.55037 | F7: =IF(VLOOKUP(TableQBRanks[[#This Row],[Player]],'Ranks w Proj'!$B:$N,13,FALSE)<0,0,VLOOKUP(TableQBRanks[[#This Row],[Player]],'Ranks w Proj'!$B:$N,13,FALSE)) -> 25.622802 | H7: 6 | I7: =IFERROR(INDEX(TableRBCalcPts[PLAYER],MATCH(TableRBRanks[[#This Row],[RK]],TableRBCalcPts[RK],0)),"") -> De'Von Achane | J7: =IFERROR(INDEX(TableRBCalcPts[TM],MATCH(TableRBRanks[[#This Row],[RK]],TableRBCalcPts[RK],0)),"") -> MIA | K7: =IFERROR(INDEX(TableRBCalcPts[BYE],MATCH(TableRBRanks[[#This Row],[RK]],TableRBCalcPts[RK],0)),"") -> 6 | L7: =IFERROR(INDEX(TableRBCalcPts[Custom],MATCH(TableRBRanks[[#This Row],[RK]],TableRBCalcPts[RK],0)),"") -> 249.37088 | M7: =IF(VLOOKUP(TableRBRanks[[#This Row],[Player]],'Ranks w Proj'!$Q:$AB,12,FALSE)<0,0,VLOOKUP(TableRBRanks[[#This Row],[Player]],'Ranks w Proj'!$Q:$AB,12,FALSE)) -> 21.848436 | O7: 6 | P7: =IFERROR(INDEX(TableWRCalcPts[PLAYER],MATCH(TableWRRanks[[#This Row],[RK]],TableWRCalcPts[RK],0)),"") -> Drake London | Q7: =IFERROR(INDEX(TableWRCalcPts[TM],MATCH(TableWRRanks[[#This Row],[RK]],TableWRCalcPts[RK],0)),"") -> ATL | R7: =IFERROR(INDEX(TableWRCalcPts[BYE],MATCH(TableWRRanks[[#This Row],[RK]],TableWRCalcPts[RK],0)),"") -> 11 | S7: =IFERROR(INDEX(TableWRCalcPts[Custom],MATCH(TableWRRanks[[#This Row],[RK]],TableWRCalcPts[RK],0)),"") -> 228.86491 | T7: =IF(VLOOKUP(TableWRRanks[[#This Row],[Player]],'Ranks w Proj'!$AE:$AO,11,FALSE)<0,0,VLOOKUP(TableWRRanks[[#This Row],[Player]],'Ranks w Proj'!$AE:$AO,11,FALSE)) -> 26.036295 | V7: 6 | W7: =IFERROR(INDEX(TableTECalcPts[PLAYER],MATCH(TableTERanks[[#This Row],[RK]],TableTECalcPts[RK],0)),"") -> George Kittle | X7: =IFERROR(INDEX(TableTECalcPts[TM],MATCH(TableTERanks[[#This Row],[RK]],TableTECalcPts[RK],0)),"") -> SF | Y7: =IFERROR(INDEX(TableTECalcPts[BYE],MATCH(TableTERanks[[#This Row],[RK]],TableTECalcPts[RK],0)),"") -> 8 | Z7: =IFERROR(INDEX(TableTECalcPts[Custom],MATCH(TableTERanks[[#This Row],[RK]],TableTECalcPts[RK],0)),"") -> 155.06993 | AA7: =IF(VLOOKUP(TableTERanks[[#This Row],[Player]],'Ranks w Proj'!$AR:$AZ,9,FALSE)<0,0,VLOOKUP(TableTERanks[[#This Row],[Player]],'Ranks w Proj'!$AR:$AZ,9,FALSE)) -> 14.501217 | AC7: 6 | AD7: =IFERROR(INDEX(TableDSTCalcPts[PLAYER],MATCH(TableDSTRanks[[#This Row],[RK]],TableDSTCalcPts[RK],0)),"") -> Minnesota Vikings | AE7: =IFERROR(INDEX(TableDSTCalcPts[BYE],MATCH(TableDSTRanks[[#This Row],[RK]],TableDSTCalcPts[RK],0)),"") -> 6 | AF7: =IFERROR(INDEX(TableDSTCalcPts[Custom],MATCH(TableDSTRanks[[#This Row],[RK]],TableDSTCalcPts[RK],0)),"") -> 135.89762 | AG7: 1
A8: 7 | B8: =IFERROR(INDEX(TableQBCalcPts[PLAYER],MATCH(TableQBRanks[[#This Row],[RK]],TableQBCalcPts[RK],0)),"") -> Patrick Mahomes | C8: =IFERROR(INDEX(TableQBCalcPts[TM],MATCH(TableQBRanks[[#This Row],[RK]],TableQBCalcPts[RK],0)),"") -> KC | D8: =IFERROR(INDEX(TableQBCalcPts[BYE],MATCH(TableQBRanks[[#This Row],[RK]],TableQBCalcPts[RK],0)),"") -> 5 | E8: =IFERROR(INDEX(TableQBCalcPts[Custom],MATCH(TableQBRanks[[#This Row],[RK]],TableQBCalcPts[RK],0)),"") -> 417.24225 | F8: =IF(VLOOKUP(TableQBRanks[[#This Row],[Player]],'Ranks w Proj'!$B:$N,13,FALSE)<0,0,VLOOKUP(TableQBRanks[[#This Row],[Player]],'Ranks w Proj'!$B:$N,13,FALSE)) -> 24.766975 | H8: 7 | I8: =IFERROR(INDEX(TableRBCalcPts[PLAYER],MATCH(TableRBRanks[[#This Row],[RK]],TableRBCalcPts[RK],0)),"") -> Chase Brown | J8: =IFERROR(INDEX(TableRBCalcPts[TM],MATCH(TableRBRanks[[#This Row],[RK]],TableRBCalcPts[RK],0)),"") -> CIN | K8: =IFERROR(INDEX(TableRBCalcPts[BYE],MATCH(TableRBRanks[[#This Row],[RK]],TableRBCalcPts[RK],0)),"") -> 6 | L8: =IFERROR(INDEX(TableRBCalcPts[Custom],MATCH(TableRBRanks[[#This Row],[RK]],TableRBCalcPts[RK],0)),"") -> 248.68447 | M8: =IF(VLOOKUP(TableRBRanks[[#This Row],[Player]],'Ranks w Proj'!$Q:$AB,12,FALSE)<0,0,VLOOKUP(TableRBRanks[[#This Row],[Player]],'Ranks w Proj'!$Q:$AB,12,FALSE)) -> 21.745267 | O8: 7 | P8: =IFERROR(INDEX(TableWRCalcPts[PLAYER],MATCH(TableWRRanks[[#This Row],[RK]],TableWRCalcPts[RK],0)),"") -> Justin Jefferson | Q8: =IFERROR(INDEX(TableWRCalcPts[TM],MATCH(TableWRRanks[[#This Row],[RK]],TableWRCalcPts[RK],0)),"") -> MIN | R8: =IFERROR(INDEX(TableWRCalcPts[BYE],MATCH(TableWRRanks[[#This Row],[RK]],TableWRCalcPts[RK],0)),"") -> 6 | S8: =IFERROR(INDEX(TableWRCalcPts[Custom],MATCH(TableWRRanks[[#This Row],[RK]],TableWRCalcPts[RK],0)),"") -> 223.24741 | T8: =IF(VLOOKUP(TableWRRanks[[#This Row],[Player]],'Ranks w Proj'!$AE:$AO,11,FALSE)<0,0,VLOOKUP(TableWRRanks[[#This Row],[Player]],'Ranks w Proj'!$AE:$AO,11,FALSE)) -> 24.980889 | V8: 7 | W8: =IFERROR(INDEX(TableTECalcPts[PLAYER],MATCH(TableTERanks[[#This Row],[RK]],TableTECalcPts[RK],0)),"") -> Harold Fannin | X8: =IFERROR(INDEX(TableTECalcPts[TM],MATCH(TableTERanks[[#This Row],[RK]],TableTECalcPts[RK],0)),"") -> CLE | Y8: =IFERROR(INDEX(TableTECalcPts[BYE],MATCH(TableTERanks[[#This Row],[RK]],TableTECalcPts[RK],0)),"") -> 11 | Z8: =IFERROR(INDEX(TableTECalcPts[Custom],MATCH(TableTERanks[[#This Row],[RK]],TableTECalcPts[RK],0)),"") -> 154.01103 | AA8: =IF(VLOOKUP(TableTERanks[[#This Row],[Player]],'Ranks w Proj'!$AR:$AZ,9,FALSE)<0,0,VLOOKUP(TableTERanks[[#This Row],[Player]],'Ranks w Proj'!$AR:$AZ,9,FALSE)) -> 14.302271 | AC8: 7 | AD8: =IFERROR(INDEX(TableDSTCalcPts[PLAYER],MATCH(TableDSTRanks[[#This Row],[RK]],TableDSTCalcPts[RK],0)),"") -> Chicago Bears | AE8: =IFERROR(INDEX(TableDSTCalcPts[BYE],MATCH(TableDSTRanks[[#This Row],[RK]],TableDSTCalcPts[RK],0)),"") -> 10 | AF8: =IFERROR(INDEX(TableDSTCalcPts[Custom],MATCH(TableDSTRanks[[#This Row],[RK]],TableDSTCalcPts[RK],0)),"") -> 129.67381 | AG8: 1
A9: 8 | B9: =IFERROR(INDEX(TableQBCalcPts[PLAYER],MATCH(TableQBRanks[[#This Row],[RK]],TableQBCalcPts[RK],0)),"") -> Jared Goff | C9: =IFERROR(INDEX(TableQBCalcPts[TM],MATCH(TableQBRanks[[#This Row],[RK]],TableQBCalcPts[RK],0)),"") -> DET | D9: =IFERROR(INDEX(TableQBCalcPts[BYE],MATCH(TableQBRanks[[#This Row],[RK]],TableQBCalcPts[RK],0)),"") -> 6 | E9: =IFERROR(INDEX(TableQBCalcPts[Custom],MATCH(TableQBRanks[[#This Row],[RK]],TableQBCalcPts[RK],0)),"") -> 415.16834 | F9: =IF(VLOOKUP(TableQBRanks[[#This Row],[Player]],'Ranks w Proj'!$B:$N,13,FALSE)<0,0,VLOOKUP(TableQBRanks[[#This Row],[Player]],'Ranks w Proj'!$B:$N,13,FALSE)) -> 23.845131 | H9: 8 | I9: =IFERROR(INDEX(TableRBCalcPts[PLAYER],MATCH(TableRBRanks[[#This Row],[RK]],TableRBCalcPts[RK],0)),"") -> Derrick Henry | J9: =IFERROR(INDEX(TableRBCalcPts[TM],MATCH(TableRBRanks[[#This Row],[RK]],TableRBCalcPts[RK],0)),"") -> BAL | K9: =IFERROR(INDEX(TableRBCalcPts[BYE],MATCH(TableRBRanks[[#This Row],[RK]],TableRBCalcPts[RK],0)),"") -> 13 | L9: =IFERROR(INDEX(TableRBCalcPts[Custom],MATCH(TableRBRanks[[#This Row],[RK]],TableRBCalcPts[RK],0)),"") -> 240.8159 | M9: =IF(VLOOKUP(TableRBRanks[[#This Row],[Player]],'Ranks w Proj'!$Q:$AB,12,FALSE)<0,0,VLOOKUP(TableRBRanks[[#This Row],[Player]],'Ranks w Proj'!$Q:$AB,12,FALSE)) -> 20.562601 | O9: 8 | P9: =IFERROR(INDEX(TableWRCalcPts[PLAYER],MATCH(TableWRRanks[[#This Row],[RK]],TableWRCalcPts[RK],0)),"") -> CeeDee Lamb | Q9: =IFERROR(INDEX(TableWRCalcPts[TM],MATCH(TableWRRanks[[#This Row],[RK]],TableWRCalcPts[RK],0)),"") -> DAL | R9: =IFERROR(INDEX(TableWRCalcPts[BYE],MATCH(TableWRRanks[[#This Row],[RK]],TableWRCalcPts[RK],0)),"") -> 14 | S9: =IFERROR(INDEX(TableWRCalcPts[Custom],MATCH(TableWRRanks[[#This Row],[RK]],TableWRCalcPts[RK],0)),"") -> 223.24357 | T9: =IF(VLOOKUP(TableWRRanks[[#This Row],[Player]],'Ranks w Proj'!$AE:$AO,11,FALSE)<0,0,VLOOKUP(TableWRRanks[[#This Row],[Player]],'Ranks w Proj'!$AE:$AO,11,FALSE)) -> 24.980169 | V9: 8 | W9: =IFERROR(INDEX(TableTECalcPts[PLAYER],MATCH(TableTERanks[[#This Row],[RK]],TableTECalcPts[RK],0)),"") -> Tucker Kraft | X9: =IFERROR(INDEX(TableTECalcPts[TM],MATCH(TableTERanks[[#This Row],[RK]],TableTECalcPts[RK],0)),"") -> GB | Y9: =IFERROR(INDEX(TableTECalcPts[BYE],MATCH(TableTERanks[[#This Row],[RK]],TableTECalcPts[RK],0)),"") -> 11 | Z9: =IFERROR(INDEX(TableTECalcPts[Custom],MATCH(TableTERanks[[#This Row],[RK]],TableTECalcPts[RK],0)),"") -> 153.12367 | AA9: =IF(VLOOKUP(TableTERanks[[#This Row],[Player]],'Ranks w Proj'!$AR:$AZ,9,FALSE)<0,0,VLOOKUP(TableTERanks[[#This Row],[Player]],'Ranks w Proj'!$AR:$AZ,9,FALSE)) -> 14.135557 | AC9: 8 | AD9: =IFERROR(INDEX(TableDSTCalcPts[PLAYER],MATCH(TableDSTRanks[[#This Row],[RK]],TableDSTCalcPts[RK],0)),"") -> Philadelphia Eagles | AE9: =IFERROR(INDEX(TableDSTCalcPts[BYE],MATCH(TableDSTRanks[[#This Row],[RK]],TableDSTCalcPts[RK],0)),"") -> 10 | AF9: =IFERROR(INDEX(TableDSTCalcPts[Custom],MATCH(TableDSTRanks[[#This Row],[RK]],TableDSTCalcPts[RK],0)),"") -> 127.72381 | AG9: 1
A10: 9 | B10: =IFERROR(INDEX(TableQBCalcPts[PLAYER],MATCH(TableQBRanks[[#This Row],[RK]],TableQBCalcPts[RK],0)),"") -> Matthew Stafford | C10: =IFERROR(INDEX(TableQBCalcPts[TM],MATCH(TableQBRanks[[#This Row],[RK]],TableQBCalcPts[RK],0)),"") -> LAR | D10: =IFERROR(INDEX(TableQBCalcPts[BYE],MATCH(TableQBRanks[[#This Row],[RK]],TableQBCalcPts[RK],0)),"") -> 11 | E10: =IFERROR(INDEX(TableQBCalcPts[Custom],MATCH(TableQBRanks[[#This Row],[RK]],TableQBCalcPts[RK],0)),"") -> 414.58253 | F10: =IF(VLOOKUP(TableQBRanks[[#This Row],[Player]],'Ranks w Proj'!$B:$N,13,FALSE)<0,0,VLOOKUP(TableQBRanks[[#This Row],[Player]],'Ranks w Proj'!$B:$N,13,FALSE)) -> 23.277173 | H10: 9 | I10: =IFERROR(INDEX(TableRBCalcPts[PLAYER],MATCH(TableRBRanks[[#This Row],[RK]],TableRBCalcPts[RK],0)),"") -> Saquon Barkley | J10: =IFERROR(INDEX(TableRBCalcPts[TM],MATCH(TableRBRanks[[#This Row],[RK]],TableRBCalcPts[RK],0)),"") -> PHI | K10: =IFERROR(INDEX(TableRBCalcPts[BYE],MATCH(TableRBRanks[[#This Row],[RK]],TableRBCalcPts[RK],0)),"") -> 10 | L10: =IFERROR(INDEX(TableRBCalcPts[Custom],MATCH(TableRBRanks[[#This Row],[RK]],TableRBCalcPts[RK],0)),"") -> 234.04588 | M10: =IF(VLOOKUP(TableRBRanks[[#This Row],[Player]],'Ranks w Proj'!$Q:$AB,12,FALSE)<0,0,VLOOKUP(TableRBRanks[[#This Row],[Player]],'Ranks w Proj'!$Q:$AB,12,FALSE)) -> 19.54505 | O10: 9 | P10: =IFERROR(INDEX(TableWRCalcPts[PLAYER],MATCH(TableWRRanks[[#This Row],[RK]],TableWRCalcPts[RK],0)),"") -> A.J. Brown | Q10: =IFERROR(INDEX(TableWRCalcPts[TM],MATCH(TableWRRanks[[#This Row],[RK]],TableWRCalcPts[RK],0)),"") -> NE | R10: =IFERROR(INDEX(TableWRCalcPts[BYE],MATCH(TableWRRanks[[#This Row],[RK]],TableWRCalcPts[RK],0)),"") -> 11 | S10: =IFERROR(INDEX(TableWRCalcPts[Custom],MATCH(TableWRRanks[[#This Row],[RK]],TableWRCalcPts[RK],0)),"") -> 221.005 | T10: =IF(VLOOKUP(TableWRRanks[[#This Row],[Player]],'Ranks w Proj'!$AE:$AO,11,FALSE)<0,0,VLOOKUP(TableWRRanks[[#This Row],[Player]],'Ranks w Proj'!$AE:$AO,11,FALSE)) -> 24.559591 | V10: 9 | W10: =IFERROR(INDEX(TableTECalcPts[PLAYER],MATCH(TableTERanks[[#This Row],[RK]],TableTECalcPts[RK],0)),"") -> Isaiah Likely | X10: =IFERROR(INDEX(TableTECalcPts[TM],MATCH(TableTERanks[[#This Row],[RK]],TableTECalcPts[RK],0)),"") -> NYG | Y10: =IFERROR(INDEX(TableTECalcPts[BYE],MATCH(TableTERanks[[#This Row],[RK]],TableTECalcPts[RK],0)),"") -> 8 | Z10: =IFERROR(INDEX(TableTECalcPts[Custom],MATCH(TableTERanks[[#This Row],[RK]],TableTECalcPts[RK],0)),"") -> 148.8925 | AA10: =IF(VLOOKUP(TableTERanks[[#This Row],[Player]],'Ranks w Proj'!$AR:$AZ,9,FALSE)<0,0,VLOOKUP(TableTERanks[[#This Row],[Player]],'Ranks w Proj'!$AR:$AZ,9,FALSE)) -> 13.340611 | AC10: 9 | AD10: =IFERROR(INDEX(TableDSTCalcPts[PLAYER],MATCH(TableDSTRanks[[#This Row],[RK]],TableDSTCalcPts[RK],0)),"") -> Los Angeles Chargers | AE10: =IFERROR(INDEX(TableDSTCalcPts[BYE],MATCH(TableDSTRanks[[#This Row],[RK]],TableDSTCalcPts[RK],0)),"") -> 7 | AF10: =IFERROR(INDEX(TableDSTCalcPts[Custom],MATCH(TableDSTRanks[[#This Row],[RK]],TableDSTCalcPts[RK],0)),"") -> 127.49048 | AG10: 1
A11: 10 | B11: =IFERROR(INDEX(TableQBCalcPts[PLAYER],MATCH(TableQBRanks[[#This Row],[RK]],TableQBCalcPts[RK],0)),"") -> Jalen Hurts | C11: =IFERROR(INDEX(TableQBCalcPts[TM],MATCH(TableQBRanks[[#This Row],[RK]],TableQBCalcPts[RK],0)),"") -> PHI | D11: =IFERROR(INDEX(TableQBCalcPts[BYE],MATCH(TableQBRanks[[#This Row],[RK]],TableQBCalcPts[RK],0)),"") -> 10 | E11: =IFERROR(INDEX(TableQBCalcPts[Custom],MATCH(TableQBRanks[[#This Row],[RK]],TableQBCalcPts[RK],0)),"") -> 411.78413 | F11: =IF(VLOOKUP(TableQBRanks[[#This Row],[Player]],'Ranks w Proj'!$B:$N,13,FALSE)<0,0,VLOOKUP(TableQBRanks[[#This Row],[Player]],'Ranks w Proj'!$B:$N,13,FALSE)) -> 22.694226 | H11: 10 | I11: =IFERROR(INDEX(TableRBCalcPts[PLAYER],MATCH(TableRBRanks[[#This Row],[RK]],TableRBCalcPts[RK],0)),"") -> Kenneth Walker | J11: =IFERROR(INDEX(TableRBCalcPts[TM],MATCH(TableRBRanks[[#This Row],[RK]],TableRBCalcPts[RK],0)),"") -> KC | K11: =IFERROR(INDEX(TableRBCalcPts[BYE],MATCH(TableRBRanks[[#This Row],[RK]],TableRBCalcPts[RK],0)),"") -> 5 | L11: =IFERROR(INDEX(TableRBCalcPts[Custom],MATCH(TableRBRanks[[#This Row],[RK]],TableRBCalcPts[RK],0)),"") -> 233.20035 | M11: =IF(VLOOKUP(TableRBRanks[[#This Row],[Player]],'Ranks w Proj'!$Q:$AB,12,FALSE)<0,0,VLOOKUP(TableRBRanks[[#This Row],[Player]],'Ranks w Proj'!$Q:$AB,12,FALSE)) -> 19.417964 | O11: 10 | P11: =IFERROR(INDEX(TableWRCalcPts[PLAYER],MATCH(TableWRRanks[[#This Row],[RK]],TableWRCalcPts[RK],0)),"") -> Nico Collins | Q11: =IFERROR(INDEX(TableWRCalcPts[TM],MATCH(TableWRRanks[[#This Row],[RK]],TableWRCalcPts[RK],0)),"") -> HOU | R11: =IFERROR(INDEX(TableWRCalcPts[BYE],MATCH(TableWRRanks[[#This Row],[RK]],TableWRCalcPts[RK],0)),"") -> 8 | S11: =IFERROR(INDEX(TableWRCalcPts[Custom],MATCH(TableWRRanks[[#This Row],[RK]],TableWRCalcPts[RK],0)),"") -> 212.48861 | T11: =IF(VLOOKUP(TableWRRanks[[#This Row],[Player]],'Ranks w Proj'!$AE:$AO,11,FALSE)<0,0,VLOOKUP(TableWRRanks[[#This Row],[Player]],'Ranks w Proj'!$AE:$AO,11,FALSE)) -> 22.959546 | V11: 10 | W11: =IFERROR(INDEX(TableTECalcPts[PLAYER],MATCH(TableTERanks[[#This Row],[RK]],TableTECalcPts[RK],0)),"") -> Travis Kelce | X11: =IFERROR(INDEX(TableTECalcPts[TM],MATCH(TableTERanks[[#This Row],[RK]],TableTECalcPts[RK],0)),"") -> KC | Y11: =IFERROR(INDEX(TableTECalcPts[BYE],MATCH(TableTERanks[[#This Row],[RK]],TableTECalcPts[RK],0)),"") -> 5 | Z11: =IFERROR(INDEX(TableTECalcPts[Custom],MATCH(TableTERanks[[#This Row],[RK]],TableTECalcPts[RK],0)),"") -> 147.70318 | AA11: =IF(VLOOKUP(TableTERanks[[#This Row],[Player]],'Ranks w Proj'!$AR:$AZ,9,FALSE)<0,0,VLOOKUP(TableTERanks[[#This Row],[Player]],'Ranks w Proj'!$AR:$AZ,9,FALSE)) -> 13.117163 | AC11: 10 | AD11: =IFERROR(INDEX(TableDSTCalcPts[PLAYER],MATCH(TableDSTRanks[[#This Row],[RK]],TableDSTCalcPts[RK],0)),"") -> Jacksonville Jaguars | AE11: =IFERROR(INDEX(TableDSTCalcPts[BYE],MATCH(TableDSTRanks[[#This Row],[RK]],TableDSTCalcPts[RK],0)),"") -> 7 | AF11: =IFERROR(INDEX(TableDSTCalcPts[Custom],MATCH(TableDSTRanks[[#This Row],[RK]],TableDSTCalcPts[RK],0)),"") -> 126.90476 | AG11: 1
A12: 11 | B12: =IFERROR(INDEX(TableQBCalcPts[PLAYER],MATCH(TableQBRanks[[#This Row],[RK]],TableQBCalcPts[RK],0)),"") -> Trevor Lawrence | C12: =IFERROR(INDEX(TableQBCalcPts[TM],MATCH(TableQBRanks[[#This Row],[RK]],TableQBCalcPts[RK],0)),"") -> JAX | D12: =IFERROR(INDEX(TableQBCalcPts[BYE],MATCH(TableQBRanks[[#This Row],[RK]],TableQBCalcPts[RK],0)),"") -> 7 | E12: =IFERROR(INDEX(TableQBCalcPts[Custom],MATCH(TableQBRanks[[#This Row],[RK]],TableQBCalcPts[RK],0)),"") -> 409.37929 | F12: =IF(VLOOKUP(TableQBRanks[[#This Row],[Player]],'Ranks w Proj'!$B:$N,13,FALSE)<0,0,VLOOKUP(TableQBRanks[[#This Row],[Player]],'Ranks w Proj'!$B:$N,13,FALSE)) -> 22.234056 | H12: 11 | I12: =IFERROR(INDEX(TableRBCalcPts[PLAYER],MATCH(TableRBRanks[[#This Row],[RK]],TableRBCalcPts[RK],0)),"") -> Omarion Hampton | J12: =IFERROR(INDEX(TableRBCalcPts[TM],MATCH(TableRBRanks[[#This Row],[RK]],TableRBCalcPts[RK],0)),"") -> LAC | K12: =IFERROR(INDEX(TableRBCalcPts[BYE],MATCH(TableRBRanks[[#This Row],[RK]],TableRBCalcPts[RK],0)),"") -> 7 | L12: =IFERROR(INDEX(TableRBCalcPts[Custom],MATCH(TableRBRanks[[#This Row],[RK]],TableRBCalcPts[RK],0)),"") -> 233.07684 | M12: =IF(VLOOKUP(TableRBRanks[[#This Row],[Player]],'Ranks w Proj'!$Q:$AB,12,FALSE)<0,0,VLOOKUP(TableRBRanks[[#This Row],[Player]],'Ranks w Proj'!$Q:$AB,12,FALSE)) -> 19.3994 | O12: 11 | P12: =IFERROR(INDEX(TableWRCalcPts[PLAYER],MATCH(TableWRRanks[[#This Row],[RK]],TableWRCalcPts[RK],0)),"") -> Tee Higgins | Q12: =IFERROR(INDEX(TableWRCalcPts[TM],MATCH(TableWRRanks[[#This Row],[RK]],TableWRCalcPts[RK],0)),"") -> CIN | R12: =IFERROR(INDEX(TableWRCalcPts[BYE],MATCH(TableWRRanks[[#This Row],[RK]],TableWRCalcPts[RK],0)),"") -> 6 | S12: =IFERROR(INDEX(TableWRCalcPts[Custom],MATCH(TableWRRanks[[#This Row],[RK]],TableWRCalcPts[RK],0)),"") -> 210.32383 | T12: =IF(VLOOKUP(TableWRRanks[[#This Row],[Player]],'Ranks w Proj'!$AE:$AO,11,FALSE)<0,0,VLOOKUP(TableWRRanks[[#This Row],[Player]],'Ranks w Proj'!$AE:$AO,11,FALSE)) -> 22.552831 | V12: 11 | W12: =IFERROR(INDEX(TableTECalcPts[PLAYER],MATCH(TableTERanks[[#This Row],[RK]],TableTECalcPts[RK],0)),"") -> Kyle Pitts | X12: =IFERROR(INDEX(TableTECalcPts[TM],MATCH(TableTERanks[[#This Row],[RK]],TableTECalcPts[RK],0)),"") -> ATL | Y12: =IFERROR(INDEX(TableTECalcPts[BYE],MATCH(TableTERanks[[#This Row],[RK]],TableTECalcPts[RK],0)),"") -> 11 | Z12: =IFERROR(INDEX(TableTECalcPts[Custom],MATCH(TableTERanks[[#This Row],[RK]],TableTECalcPts[RK],0)),"") -> 141.23637 | AA12: =IF(VLOOKUP(TableTERanks[[#This Row],[Player]],'Ranks w Proj'!$AR:$AZ,9,FALSE)<0,0,VLOOKUP(TableTERanks[[#This Row],[Player]],'Ranks w Proj'!$AR:$AZ,9,FALSE)) -> 11.902192 | AC12: 11 | AD12: =IFERROR(INDEX(TableDSTCalcPts[PLAYER],MATCH(TableDSTRanks[[#This Row],[RK]],TableDSTCalcPts[RK],0)),"") -> Atlanta Falcons | AE12: =IFERROR(INDEX(TableDSTCalcPts[BYE],MATCH(TableDSTRanks[[#This Row],[RK]],TableDSTCalcPts[RK],0)),"") -> 11 | AF12: =IFERROR(INDEX(TableDSTCalcPts[Custom],MATCH(TableDSTRanks[[#This Row],[RK]],TableDSTCalcPts[RK],0)),"") -> 125.45 | AG12: 1
A13: 12 | B13: =IFERROR(INDEX(TableQBCalcPts[PLAYER],MATCH(TableQBRanks[[#This Row],[RK]],TableQBCalcPts[RK],0)),"") -> Caleb Williams | C13: =IFERROR(INDEX(TableQBCalcPts[TM],MATCH(TableQBRanks[[#This Row],[RK]],TableQBCalcPts[RK],0)),"") -> CHI | D13: =IFERROR(INDEX(TableQBCalcPts[BYE],MATCH(TableQBRanks[[#This Row],[RK]],TableQBCalcPts[RK],0)),"") -> 10 | E13: =IFERROR(INDEX(TableQBCalcPts[Custom],MATCH(TableQBRanks[[#This Row],[RK]],TableQBCalcPts[RK],0)),"") -> 406.47585 | F13: =IF(VLOOKUP(TableQBRanks[[#This Row],[Player]],'Ranks w Proj'!$B:$N,13,FALSE)<0,0,VLOOKUP(TableQBRanks[[#This Row],[Player]],'Ranks w Proj'!$B:$N,13,FALSE)) -> 21.687693 | H13: 12 | I13: =IFERROR(INDEX(TableRBCalcPts[PLAYER],MATCH(TableRBRanks[[#This Row],[RK]],TableRBCalcPts[RK],0)),"") -> Ashton Jeanty | J13: =IFERROR(INDEX(TableRBCalcPts[TM],MATCH(TableRBRanks[[#This Row],[RK]],TableRBCalcPts[RK],0)),"") -> LV | K13: =IFERROR(INDEX(TableRBCalcPts[BYE],MATCH(TableRBRanks[[#This Row],[RK]],TableRBCalcPts[RK],0)),"") -> 13 | L13: =IFERROR(INDEX(TableRBCalcPts[Custom],MATCH(TableRBRanks[[#This Row],[RK]],TableRBCalcPts[RK],0)),"") -> 233.06399 | M13: =IF(VLOOKUP(TableRBRanks[[#This Row],[Player]],'Ranks w Proj'!$Q:$AB,12,FALSE)<0,0,VLOOKUP(TableRBRanks[[#This Row],[Player]],'Ranks w Proj'!$Q:$AB,12,FALSE)) -> 19.397469 | O13: 12 | P13: =IFERROR(INDEX(TableWRCalcPts[PLAYER],MATCH(TableWRRanks[[#This Row],[RK]],TableWRCalcPts[RK],0)),"") -> Tetairoa McMillan | Q13: =IFERROR(INDEX(TableWRCalcPts[TM],MATCH(TableWRRanks[[#This Row],[RK]],TableWRCalcPts[RK],0)),"") -> CAR | R13: =IFERROR(INDEX(TableWRCalcPts[BYE],MATCH(TableWRRanks[[#This Row],[RK]],TableWRCalcPts[RK],0)),"") -> 5 | S13: =IFERROR(INDEX(TableWRCalcPts[Custom],MATCH(TableWRRanks[[#This Row],[RK]],TableWRCalcPts[RK],0)),"") -> 207.85592 | T13: =IF(VLOOKUP(TableWRRanks[[#This Row],[Player]],'Ranks w Proj'!$AE:$AO,11,FALSE)<0,0,VLOOKUP(TableWRRanks[[#This Row],[Player]],'Ranks w Proj'!$AE:$AO,11,FALSE)) -> 22.089164 | V13: 12 | W13: =IFERROR(INDEX(TableTECalcPts[PLAYER],MATCH(TableTERanks[[#This Row],[RK]],TableTECalcPts[RK],0)),"") -> Dalton Kincaid | X13: =IFERROR(INDEX(TableTECalcPts[TM],MATCH(TableTERanks[[#This Row],[RK]],TableTECalcPts[RK],0)),"") -> BUF | Y13: =IFERROR(INDEX(TableTECalcPts[BYE],MATCH(TableTERanks[[#This Row],[RK]],TableTECalcPts[RK],0)),"") -> 7 | Z13: =IFERROR(INDEX(TableTECalcPts[Custom],MATCH(TableTERanks[[#This Row],[RK]],TableTECalcPts[RK],0)),"") -> 137.45097 | AA13: =IF(VLOOKUP(TableTERanks[[#This Row],[Player]],'Ranks w Proj'!$AR:$AZ,9,FALSE)<0,0,VLOOKUP(TableTERanks[[#This Row],[Player]],'Ranks w Proj'!$AR:$AZ,9,FALSE)) -> 11.190997 | AC13: 12 | AD13: =IFERROR(INDEX(TableDSTCalcPts[PLAYER],MATCH(TableDSTRanks[[#This Row],[RK]],TableDSTCalcPts[RK],0)),"") -> Detroit Lions | AE13: =IFERROR(INDEX(TableDSTCalcPts[BYE],MATCH(TableDSTRanks[[#This Row],[RK]],TableDSTCalcPts[RK],0)),"") -> 6 | AF13: =IFERROR(INDEX(TableDSTCalcPts[Custom],MATCH(TableDSTRanks[[#This Row],[RK]],TableDSTCalcPts[RK],0)),"") -> 123.3119 | AG13: 0
... A33: 32 | B33: =IFERROR(INDEX(TableQBCalcPts[PLAYER],MATCH(TableQBRanks[[#This Row],[RK]],TableQBCalcPts[RK],0)),"") -> Shedeur Sanders | C33: =IFERROR(INDEX(TableQBCalcPts[TM],MATCH(TableQBRanks[[#This Row],[RK]],TableQBCalcPts[RK],0)),"") -> CLE | D33: =IFERROR(INDEX(TableQBCalcPts[BYE],MATCH(TableQBRanks[[#This Row],[RK]],TableQBCalcPts[RK],0)),"") -> 11 | E33: =IFERROR(INDEX(TableQBCalcPts[Custom],MATCH(TableQBRanks[[#This Row],[RK]],TableQBCalcPts[RK],0)),"") -> 156.36883 | F33: =IF(VLOOKUP(TableQBRanks[[#This Row],[Player]],'Ranks w Proj'!$B:$N,13,FALSE)<0,0,VLOOKUP(TableQBRanks[[#This Row],[Player]],'Ranks w Proj'!$B:$N,13,FALSE)) -> 0 | H33: 32 | I33: =IFERROR(INDEX(TableRBCalcPts[PLAYER],MATCH(TableRBRanks[[#This Row],[RK]],TableRBCalcPts[RK],0)),"") -> RJ Harvey | J33: =IFERROR(INDEX(TableRBCalcPts[TM],MATCH(TableRBRanks[[#This Row],[RK]],TableRBCalcPts[RK],0)),"") -> DEN | K33: =IFERROR(INDEX(TableRBCalcPts[BYE],MATCH(TableRBRanks[[#This Row],[RK]],TableRBCalcPts[RK],0)),"") -> 10 | L33: =IFERROR(INDEX(TableRBCalcPts[Custom],MATCH(TableRBRanks[[#This Row],[RK]],TableRBCalcPts[RK],0)),"") -> 166.07855 | M33: =IF(VLOOKUP(TableRBRanks[[#This Row],[Player]],'Ranks w Proj'!$Q:$AB,12,FALSE)<0,0,VLOOKUP(TableRBRanks[[#This Row],[Player]],'Ranks w Proj'!$Q:$AB,12,FALSE)) -> 9.3293868 | O33: 32 | P33: =IFERROR(INDEX(TableWRCalcPts[PLAYER],MATCH(TableWRRanks[[#This Row],[RK]],TableWRCalcPts[RK],0)),"") -> Courtland Sutton | Q33: =IFERROR(INDEX(TableWRCalcPts[TM],MATCH(TableWRRanks[[#This Row],[RK]],TableWRCalcPts[RK],0)),"") -> DEN | R33: =IFERROR(INDEX(TableWRCalcPts[BYE],MATCH(TableWRRanks[[#This Row],[RK]],TableWRCalcPts[RK],0)),"") -> 10 | S33: =IFERROR(INDEX(TableWRCalcPts[Custom],MATCH(TableWRRanks[[#This Row],[RK]],TableWRCalcPts[RK],0)),"") -> 170.42849 | T33: =IF(VLOOKUP(TableWRRanks[[#This Row],[Player]],'Ranks w Proj'!$AE:$AO,11,FALSE)<0,0,VLOOKUP(TableWRRanks[[#This Row],[Player]],'Ranks w Proj'!$AE:$AO,11,FALSE)) -> 15.057366 | V33: 32 | W33: =IFERROR(INDEX(TableTECalcPts[PLAYER],MATCH(TableTERanks[[#This Row],[RK]],TableTECalcPts[RK],0)),"") -> Evan Engram | X33: =IFERROR(INDEX(TableTECalcPts[TM],MATCH(TableTERanks[[#This Row],[RK]],TableTECalcPts[RK],0)),"") -> DEN | Y33: =IFERROR(INDEX(TableTECalcPts[BYE],MATCH(TableTERanks[[#This Row],[RK]],TableTECalcPts[RK],0)),"") -> 10 | Z33: =IFERROR(INDEX(TableTECalcPts[Custom],MATCH(TableTERanks[[#This Row],[RK]],TableTECalcPts[RK],0)),"") -> 71.134067 | AA33: =IF(VLOOKUP(TableTERanks[[#This Row],[Player]],'Ranks w Proj'!$AR:$AZ,9,FALSE)<0,0,VLOOKUP(TableTERanks[[#This Row],[Player]],'Ranks w Proj'!$AR:$AZ,9,FALSE)) -> 0 | AC33: 32 | AD33: =IFERROR(INDEX(TableDSTCalcPts[PLAYER],MATCH(TableDSTRanks[[#This Row],[RK]],TableDSTCalcPts[RK],0)),"") -> New York Jets | AE33: =IFERROR(INDEX(TableDSTCalcPts[BYE],MATCH(TableDSTRanks[[#This Row],[RK]],TableDSTCalcPts[RK],0)),"") -> 13 | AF33: =IFERROR(INDEX(TableDSTCalcPts[Custom],MATCH(TableDSTRanks[[#This Row],[RK]],TableDSTCalcPts[RK],0)),"") -> 100.11905 | AG33: 0
A34: 33 | B34: =IFERROR(INDEX(TableQBCalcPts[PLAYER],MATCH(TableQBRanks[[#This Row],[RK]],TableQBCalcPts[RK],0)),"") -> Deshaun Watson | C34: =IFERROR(INDEX(TableQBCalcPts[TM],MATCH(TableQBRanks[[#This Row],[RK]],TableQBCalcPts[RK],0)),"") -> CLE | D34: =IFERROR(INDEX(TableQBCalcPts[BYE],MATCH(TableQBRanks[[#This Row],[RK]],TableQBCalcPts[RK],0)),"") -> 11 | E34: =IFERROR(INDEX(TableQBCalcPts[Custom],MATCH(TableQBRanks[[#This Row],[RK]],TableQBCalcPts[RK],0)),"") -> 148.15984 | F34: =IF(VLOOKUP(TableQBRanks[[#This Row],[Player]],'Ranks w Proj'!$B:$N,13,FALSE)<0,0,VLOOKUP(TableQBRanks[[#This Row],[Player]],'Ranks w Proj'!$B:$N,13,FALSE)) -> 0 | H34: 33 | I34: =IFERROR(INDEX(TableRBCalcPts[PLAYER],MATCH(TableRBRanks[[#This Row],[RK]],TableRBCalcPts[RK],0)),"") -> Jaylen Warren | J34: =IFERROR(INDEX(TableRBCalcPts[TM],MATCH(TableRBRanks[[#This Row],[RK]],TableRBCalcPts[RK],0)),"") -> PIT | K34: =IFERROR(INDEX(TableRBCalcPts[BYE],MATCH(TableRBRanks[[#This Row],[RK]],TableRBCalcPts[RK],0)),"") -> 9 | L34: =IFERROR(INDEX(TableRBCalcPts[Custom],MATCH(TableRBRanks[[#This Row],[RK]],TableRBCalcPts[RK],0)),"") -> 165.4694 | M34: =IF(VLOOKUP(TableRBRanks[[#This Row],[Player]],'Ranks w Proj'!$Q:$AB,12,FALSE)<0,0,VLOOKUP(TableRBRanks[[#This Row],[Player]],'Ranks w Proj'!$Q:$AB,12,FALSE)) -> 9.237829 | O34: 33 | P34: =IFERROR(INDEX(TableWRCalcPts[PLAYER],MATCH(TableWRRanks[[#This Row],[RK]],TableWRCalcPts[RK],0)),"") -> Makai Lemon | Q34: =IFERROR(INDEX(TableWRCalcPts[TM],MATCH(TableWRRanks[[#This Row],[RK]],TableWRCalcPts[RK],0)),"") -> PHI | R34: =IFERROR(INDEX(TableWRCalcPts[BYE],MATCH(TableWRRanks[[#This Row],[RK]],TableWRCalcPts[RK],0)),"") -> 10 | S34: =IFERROR(INDEX(TableWRCalcPts[Custom],MATCH(TableWRRanks[[#This Row],[RK]],TableWRCalcPts[RK],0)),"") -> 169.40745 | T34: =IF(VLOOKUP(TableWRRanks[[#This Row],[Player]],'Ranks w Proj'!$AE:$AO,11,FALSE)<0,0,VLOOKUP(TableWRRanks[[#This Row],[Player]],'Ranks w Proj'!$AE:$AO,11,FALSE)) -> 14.865536 | V34: 33 | W34: =IFERROR(INDEX(TableTECalcPts[PLAYER],MATCH(TableTERanks[[#This Row],[RK]],TableTECalcPts[RK],0)),"") -> Mason Taylor | X34: =IFERROR(INDEX(TableTECalcPts[TM],MATCH(TableTERanks[[#This Row],[RK]],TableTECalcPts[RK],0)),"") -> NYJ | Y34: =IFERROR(INDEX(TableTECalcPts[BYE],MATCH(TableTERanks[[#This Row],[RK]],TableTECalcPts[RK],0)),"") -> 13 | Z34: =IFERROR(INDEX(TableTECalcPts[Custom],MATCH(TableTERanks[[#This Row],[RK]],TableTECalcPts[RK],0)),"") -> 64.620107 | AA34: =IF(VLOOKUP(TableTERanks[[#This Row],[Player]],'Ranks w Proj'!$AR:$AZ,9,FALSE)<0,0,VLOOKUP(TableTERanks[[#This Row],[Player]],'Ranks w Proj'!$AR:$AZ,9,FALSE)) -> 0
A35: 34 | B35: =IFERROR(INDEX(TableQBCalcPts[PLAYER],MATCH(TableQBRanks[[#This Row],[RK]],TableQBCalcPts[RK],0)),"") -> Fernando Mendoza | C35: =IFERROR(INDEX(TableQBCalcPts[TM],MATCH(TableQBRanks[[#This Row],[RK]],TableQBCalcPts[RK],0)),"") -> LV | D35: =IFERROR(INDEX(TableQBCalcPts[BYE],MATCH(TableQBRanks[[#This Row],[RK]],TableQBCalcPts[RK],0)),"") -> 13 | E35: =IFERROR(INDEX(TableQBCalcPts[Custom],MATCH(TableQBRanks[[#This Row],[RK]],TableQBCalcPts[RK],0)),"") -> 134.27768 | F35: =IF(VLOOKUP(TableQBRanks[[#This Row],[Player]],'Ranks w Proj'!$B:$N,13,FALSE)<0,0,VLOOKUP(TableQBRanks[[#This Row],[Player]],'Ranks w Proj'!$B:$N,13,FALSE)) -> 0 | H35: 34 | I35: =IFERROR(INDEX(TableRBCalcPts[PLAYER],MATCH(TableRBRanks[[#This Row],[RK]],TableRBCalcPts[RK],0)),"") -> Kyle Monangai | J35: =IFERROR(INDEX(TableRBCalcPts[TM],MATCH(TableRBRanks[[#This Row],[RK]],TableRBCalcPts[RK],0)),"") -> CHI | K35: =IFERROR(INDEX(TableRBCalcPts[BYE],MATCH(TableRBRanks[[#This Row],[RK]],TableRBCalcPts[RK],0)),"") -> 10 | L35: =IFERROR(INDEX(TableRBCalcPts[Custom],MATCH(TableRBRanks[[#This Row],[RK]],TableRBCalcPts[RK],0)),"") -> 147.64126 | M35: =IF(VLOOKUP(TableRBRanks[[#This Row],[Player]],'Ranks w Proj'!$Q:$AB,12,FALSE)<0,0,VLOOKUP(TableRBRanks[[#This Row],[Player]],'Ranks w Proj'!$Q:$AB,12,FALSE)) -> 6.5582149 | O35: 34 | P35: =IFERROR(INDEX(TableWRCalcPts[PLAYER],MATCH(TableWRRanks[[#This Row],[RK]],TableWRCalcPts[RK],0)),"") -> Jordan Addison | Q35: =IFERROR(INDEX(TableWRCalcPts[TM],MATCH(TableWRRanks[[#This Row],[RK]],TableWRCalcPts[RK],0)),"") -> MIN | R35: =IFERROR(INDEX(TableWRCalcPts[BYE],MATCH(TableWRRanks[[#This Row],[RK]],TableWRCalcPts[RK],0)),"") -> 6 | S35: =IFERROR(INDEX(TableWRCalcPts[Custom],MATCH(TableWRRanks[[#This Row],[RK]],TableWRCalcPts[RK],0)),"") -> 168.53891 | T35: =IF(VLOOKUP(TableWRRanks[[#This Row],[Player]],'Ranks w Proj'!$AE:$AO,11,FALSE)<0,0,VLOOKUP(TableWRRanks[[#This Row],[Player]],'Ranks w Proj'!$AE:$AO,11,FALSE)) -> 14.702356 | V35: 34 | W35: =IFERROR(INDEX(TableTECalcPts[PLAYER],MATCH(TableTERanks[[#This Row],[RK]],TableTECalcPts[RK],0)),"") -> Darnell Washington | X35: =IFERROR(INDEX(TableTECalcPts[TM],MATCH(TableTERanks[[#This Row],[RK]],TableTECalcPts[RK],0)),"") -> PIT | Y35: =IFERROR(INDEX(TableTECalcPts[BYE],MATCH(TableTERanks[[#This Row],[RK]],TableTECalcPts[RK],0)),"") -> 9 | Z35: =IFERROR(INDEX(TableTECalcPts[Custom],MATCH(TableTERanks[[#This Row],[RK]],TableTECalcPts[RK],0)),"") -> 63.316145 | AA35: =IF(VLOOKUP(TableTERanks[[#This Row],[Player]],'Ranks w Proj'!$AR:$AZ,9,FALSE)<0,0,VLOOKUP(TableTERanks[[#This Row],[Player]],'Ranks w Proj'!$AR:$AZ,9,FALSE)) -> 0
A36: 35 | B36: =IFERROR(INDEX(TableQBCalcPts[PLAYER],MATCH(TableQBRanks[[#This Row],[RK]],TableQBCalcPts[RK],0)),"") -> Michael Penix | C36: =IFERROR(INDEX(TableQBCalcPts[TM],MATCH(TableQBRanks[[#This Row],[RK]],TableQBCalcPts[RK],0)),"") -> ATL | D36: =IFERROR(INDEX(TableQBCalcPts[BYE],MATCH(TableQBRanks[[#This Row],[RK]],TableQBCalcPts[RK],0)),"") -> 11 | E36: =IFERROR(INDEX(TableQBCalcPts[Custom],MATCH(TableQBRanks[[#This Row],[RK]],TableQBCalcPts[RK],0)),"") -> 41.951259 | F36: =IF(VLOOKUP(TableQBRanks[[#This Row],[Player]],'Ranks w Proj'!$B:$N,13,FALSE)<0,0,VLOOKUP(TableQBRanks[[#This Row],[Player]],'Ranks w Proj'!$B:$N,13,FALSE)) -> 0 | H36: 35 | I36: =IFERROR(INDEX(TableRBCalcPts[PLAYER],MATCH(TableRBRanks[[#This Row],[RK]],TableRBCalcPts[RK],0)),"") -> Jordan Mason | J36: =IFERROR(INDEX(TableRBCalcPts[TM],MATCH(TableRBRanks[[#This Row],[RK]],TableRBCalcPts[RK],0)),"") -> MIN | K36: =IFERROR(INDEX(TableRBCalcPts[BYE],MATCH(TableRBRanks[[#This Row],[RK]],TableRBCalcPts[RK],0)),"") -> 6 | L36: =IFERROR(INDEX(TableRBCalcPts[Custom],MATCH(TableRBRanks[[#This Row],[RK]],TableRBCalcPts[RK],0)),"") -> 132.30676 | M36: =IF(VLOOKUP(TableRBRanks[[#This Row],[Player]],'Ranks w Proj'!$Q:$AB,12,FALSE)<0,0,VLOOKUP(TableRBRanks[[#This Row],[Player]],'Ranks w Proj'!$Q:$AB,12,FALSE)) -> 4.2533998 | O36: 35 | P36: =IFERROR(INDEX(TableWRCalcPts[PLAYER],MATCH(TableWRRanks[[#This Row],[RK]],TableWRCalcPts[RK],0)),"") -> Quentin Johnston | Q36: =IFERROR(INDEX(TableWRCalcPts[TM],MATCH(TableWRRanks[[#This Row],[RK]],TableWRCalcPts[RK],0)),"") -> LAC | R36: =IFERROR(INDEX(TableWRCalcPts[BYE],MATCH(TableWRRanks[[#This Row],[RK]],TableWRCalcPts[RK],0)),"") -> 7 | S36: =IFERROR(INDEX(TableWRCalcPts[Custom],MATCH(TableWRRanks[[#This Row],[RK]],TableWRCalcPts[RK],0)),"") -> 164.51076 | T36: =IF(VLOOKUP(TableWRRanks[[#This Row],[Player]],'Ranks w Proj'!$AE:$AO,11,FALSE)<0,0,VLOOKUP(TableWRRanks[[#This Row],[Player]],'Ranks w Proj'!$AE:$AO,11,FALSE)) -> 13.945555 | V36: 35 | W36: =IFERROR(INDEX(TableTECalcPts[PLAYER],MATCH(TableTERanks[[#This Row],[RK]],TableTECalcPts[RK],0)),"") -> Dawson Knox | X36: =IFERROR(INDEX(TableTECalcPts[TM],MATCH(TableTERanks[[#This Row],[RK]],TableTECalcPts[RK],0)),"") -> BUF | Y36: =IFERROR(INDEX(TableTECalcPts[BYE],MATCH(TableTERanks[[#This Row],[RK]],TableTECalcPts[RK],0)),"") -> 7 | Z36: =IFERROR(INDEX(TableTECalcPts[Custom],MATCH(TableTERanks[[#This Row],[RK]],TableTECalcPts[RK],0)),"") -> 61.473813 | AA36: =IF(VLOOKUP(TableTERanks[[#This Row],[Player]],'Ranks w Proj'!$AR:$AZ,9,FALSE)<0,0,VLOOKUP(TableTERanks[[#This Row],[Player]],'Ranks w Proj'!$AR:$AZ,9,FALSE)) -> 0
A37: 36 | B37: =IFERROR(INDEX(TableQBCalcPts[PLAYER],MATCH(TableQBRanks[[#This Row],[RK]],TableQBCalcPts[RK],0)),"") -> Anthony Richardson | C37: =IFERROR(INDEX(TableQBCalcPts[TM],MATCH(TableQBRanks[[#This Row],[RK]],TableQBCalcPts[RK],0)),"") -> IND | D37: =IFERROR(INDEX(TableQBCalcPts[BYE],MATCH(TableQBRanks[[#This Row],[RK]],TableQBCalcPts[RK],0)),"") -> 13 | E37: =IFERROR(INDEX(TableQBCalcPts[Custom],MATCH(TableQBRanks[[#This Row],[RK]],TableQBCalcPts[RK],0)),"") -> 34.144033 | F37: =IF(VLOOKUP(TableQBRanks[[#This Row],[Player]],'Ranks w Proj'!$B:$N,13,FALSE)<0,0,VLOOKUP(TableQBRanks[[#This Row],[Player]],'Ranks w Proj'!$B:$N,13,FALSE)) -> 0 | H37: 36 | I37: =IFERROR(INDEX(TableRBCalcPts[PLAYER],MATCH(TableRBRanks[[#This Row],[RK]],TableRBCalcPts[RK],0)),"") -> Blake Corum | J37: =IFERROR(INDEX(TableRBCalcPts[TM],MATCH(TableRBRanks[[#This Row],[RK]],TableRBCalcPts[RK],0)),"") -> LAR | K37: =IFERROR(INDEX(TableRBCalcPts[BYE],MATCH(TableRBRanks[[#This Row],[RK]],TableRBCalcPts[RK],0)),"") -> 11 | L37: =IFERROR(INDEX(TableRBCalcPts[Custom],MATCH(TableRBRanks[[#This Row],[RK]],TableRBCalcPts[RK],0)),"") -> 132.20471 | M37: =IF(VLOOKUP(TableRBRanks[[#This Row],[Player]],'Ranks w Proj'!$Q:$AB,12,FALSE)<0,0,VLOOKUP(TableRBRanks[[#This Row],[Player]],'Ranks w Proj'!$Q:$AB,12,FALSE)) -> 4.2380622 | O37: 36 | P37: =IFERROR(INDEX(TableWRCalcPts[PLAYER],MATCH(TableWRRanks[[#This Row],[RK]],TableWRCalcPts[RK],0)),"") -> Jordyn Tyson | Q37: =IFERROR(INDEX(TableWRCalcPts[TM],MATCH(TableWRRanks[[#This Row],[RK]],TableWRCalcPts[RK],0)),"") -> NO | R37: =IFERROR(INDEX(TableWRCalcPts[BYE],MATCH(TableWRRanks[[#This Row],[RK]],TableWRCalcPts[RK],0)),"") -> 8 | S37: =IFERROR(INDEX(TableWRCalcPts[Custom],MATCH(TableWRRanks[[#This Row],[RK]],TableWRCalcPts[RK],0)),"") -> 163.96883 | T37: =IF(VLOOKUP(TableWRRanks[[#This Row],[Player]],'Ranks w Proj'!$AE:$AO,11,FALSE)<0,0,VLOOKUP(TableWRRanks[[#This Row],[Player]],'Ranks w Proj'!$AE:$AO,11,FALSE)) -> 13.843737 | V37: 36 | W37: =IFERROR(INDEX(TableTECalcPts[PLAYER],MATCH(TableTERanks[[#This Row],[RK]],TableTECalcPts[RK],0)),"") -> Colby Parkinson | X37: =IFERROR(INDEX(TableTECalcPts[TM],MATCH(TableTERanks[[#This Row],[RK]],TableTECalcPts[RK],0)),"") -> LAR | Y37: =IFERROR(INDEX(TableTECalcPts[BYE],MATCH(TableTERanks[[#This Row],[RK]],TableTECalcPts[RK],0)),"") -> 11 | Z37: =IFERROR(INDEX(TableTECalcPts[Custom],MATCH(TableTERanks[[#This Row],[RK]],TableTECalcPts[RK],0)),"") -> 61.096126 | AA37: =IF(VLOOKUP(TableTERanks[[#This Row],[Player]],'Ranks w Proj'!$AR:$AZ,9,FALSE)<0,0,VLOOKUP(TableTERanks[[#This Row],[Player]],'Ranks w Proj'!$AR:$AZ,9,FALSE)) -> 0
A38: 37 | B38: =IFERROR(INDEX(TableQBCalcPts[PLAYER],MATCH(TableQBRanks[[#This Row],[RK]],TableQBCalcPts[RK],0)),"") -> Carson Beck | C38: =IFERROR(INDEX(TableQBCalcPts[TM],MATCH(TableQBRanks[[#This Row],[RK]],TableQBCalcPts[RK],0)),"") -> ARI | D38: =IFERROR(INDEX(TableQBCalcPts[BYE],MATCH(TableQBRanks[[#This Row],[RK]],TableQBCalcPts[RK],0)),"") -> 14 | E38: =IFERROR(INDEX(TableQBCalcPts[Custom],MATCH(TableQBRanks[[#This Row],[RK]],TableQBCalcPts[RK],0)),"") -> 22.154241 | F38: =IF(VLOOKUP(TableQBRanks[[#This Row],[Player]],'Ranks w Proj'!$B:$N,13,FALSE)<0,0,VLOOKUP(TableQBRanks[[#This Row],[Player]],'Ranks w Proj'!$B:$N,13,FALSE)) -> 0 | H38: 37 | I38: =IFERROR(INDEX(TableRBCalcPts[PLAYER],MATCH(TableRBRanks[[#This Row],[RK]],TableRBCalcPts[RK],0)),"") -> Aaron Jones | J38: =IFERROR(INDEX(TableRBCalcPts[TM],MATCH(TableRBRanks[[#This Row],[RK]],TableRBCalcPts[RK],0)),"") -> MIN | K38: =IFERROR(INDEX(TableRBCalcPts[BYE],MATCH(TableRBRanks[[#This Row],[RK]],TableRBCalcPts[RK],0)),"") -> 6 | L38: =IFERROR(INDEX(TableRBCalcPts[Custom],MATCH(TableRBRanks[[#This Row],[RK]],TableRBCalcPts[RK],0)),"") -> 130.92159 | M38: =IF(VLOOKUP(TableRBRanks[[#This Row],[Player]],'Ranks w Proj'!$Q:$AB,12,FALSE)<0,0,VLOOKUP(TableRBRanks[[#This Row],[Player]],'Ranks w Proj'!$Q:$AB,12,FALSE)) -> 4.0452048 | O38: 37 | P38: =IFERROR(INDEX(TableWRCalcPts[PLAYER],MATCH(TableWRRanks[[#This Row],[RK]],TableWRCalcPts[RK],0)),"") -> DK Metcalf | Q38: =IFERROR(INDEX(TableWRCalcPts[TM],MATCH(TableWRRanks[[#This Row],[RK]],TableWRCalcPts[RK],0)),"") -> PIT | R38: =IFERROR(INDEX(TableWRCalcPts[BYE],MATCH(TableWRRanks[[#This Row],[RK]],TableWRCalcPts[RK],0)),"") -> 9 | S38: =IFERROR(INDEX(TableWRCalcPts[Custom],MATCH(TableWRRanks[[#This Row],[RK]],TableWRCalcPts[RK],0)),"") -> 162.91606 | T38: =IF(VLOOKUP(TableWRRanks[[#This Row],[Player]],'Ranks w Proj'!$AE:$AO,11,FALSE)<0,0,VLOOKUP(TableWRRanks[[#This Row],[Player]],'Ranks w Proj'!$AE:$AO,11,FALSE)) -> 13.645944 | V38: 37 | W38: =IFERROR(INDEX(TableTECalcPts[PLAYER],MATCH(TableTERanks[[#This Row],[RK]],TableTECalcPts[RK],0)),"") -> Ja'Tavion Sanders | X38: =IFERROR(INDEX(TableTECalcPts[TM],MATCH(TableTERanks[[#This Row],[RK]],TableTECalcPts[RK],0)),"") -> CAR | Y38: =IFERROR(INDEX(TableTECalcPts[BYE],MATCH(TableTERanks[[#This Row],[RK]],TableTECalcPts[RK],0)),"") -> 5 | Z38: =IFERROR(INDEX(TableTECalcPts[Custom],MATCH(TableTERanks[[#This Row],[RK]],TableTECalcPts[RK],0)),"") -> 52.13649 | AA38: =IF(VLOOKUP(TableTERanks[[#This Row],[Player]],'Ranks w Proj'!$AR:$AZ,9,FALSE)<0,0,VLOOKUP(TableTERanks[[#This Row],[Player]],'Ranks w Proj'!$AR:$AZ,9,FALSE)) -> 0
A39: 38 | B39: =IFERROR(INDEX(TableQBCalcPts[PLAYER],MATCH(TableQBRanks[[#This Row],[RK]],TableQBCalcPts[RK],0)),"") -> Justin Fields | C39: =IFERROR(INDEX(TableQBCalcPts[TM],MATCH(TableQBRanks[[#This Row],[RK]],TableQBCalcPts[RK],0)),"") -> KC | D39: =IFERROR(INDEX(TableQBCalcPts[BYE],MATCH(TableQBRanks[[#This Row],[RK]],TableQBCalcPts[RK],0)),"") -> 5 | E39: =IFERROR(INDEX(TableQBCalcPts[Custom],MATCH(TableQBRanks[[#This Row],[RK]],TableQBCalcPts[RK],0)),"") -> 20.709035 | F39: =IF(VLOOKUP(TableQBRanks[[#This Row],[Player]],'Ranks w Proj'!$B:$N,13,FALSE)<0,0,VLOOKUP(TableQBRanks[[#This Row],[Player]],'Ranks w Proj'!$B:$N,13,FALSE)) -> 0 | H39: 38 | I39: =IFERROR(INDEX(TableRBCalcPts[PLAYER],MATCH(TableRBRanks[[#This Row],[RK]],TableRBCalcPts[RK],0)),"") -> Jonathon Brooks | J39: =IFERROR(INDEX(TableRBCalcPts[TM],MATCH(TableRBRanks[[#This Row],[RK]],TableRBCalcPts[RK],0)),"") -> CAR | K39: =IFERROR(INDEX(TableRBCalcPts[BYE],MATCH(TableRBRanks[[#This Row],[RK]],TableRBCalcPts[RK],0)),"") -> 5 | L39: =IFERROR(INDEX(TableRBCalcPts[Custom],MATCH(TableRBRanks[[#This Row],[RK]],TableRBCalcPts[RK],0)),"") -> 126.32116 | M39: =IF(VLOOKUP(TableRBRanks[[#This Row],[Player]],'Ranks w Proj'!$Q:$AB,12,FALSE)<0,0,VLOOKUP(TableRBRanks[[#This Row],[Player]],'Ranks w Proj'!$Q:$AB,12,FALSE)) -> 3.353749 | O39: 38 | P39: =IFERROR(INDEX(TableWRCalcPts[PLAYER],MATCH(TableWRRanks[[#This Row],[RK]],TableWRCalcPts[RK],0)),"") -> Michael Pittman | Q39: =IFERROR(INDEX(TableWRCalcPts[TM],MATCH(TableWRRanks[[#This Row],[RK]],TableWRCalcPts[RK],0)),"") -> PIT | R39: =IFERROR(INDEX(TableWRCalcPts[BYE],MATCH(TableWRRanks[[#This Row],[RK]],TableWRCalcPts[RK],0)),"") -> 9 | S39: =IFERROR(INDEX(TableWRCalcPts[Custom],MATCH(TableWRRanks[[#This Row],[RK]],TableWRCalcPts[RK],0)),"") -> 161.35338 | T39: =IF(VLOOKUP(TableWRRanks[[#This Row],[Player]],'Ranks w Proj'!$AE:$AO,11,FALSE)<0,0,VLOOKUP(TableWRRanks[[#This Row],[Player]],'Ranks w Proj'!$AE:$AO,11,FALSE)) -> 13.352352 | V39: 38 | W39: =IFERROR(INDEX(TableTECalcPts[PLAYER],MATCH(TableTERanks[[#This Row],[RK]],TableTECalcPts[RK],0)),"") -> Eli Raridon | X39: =IFERROR(INDEX(TableTECalcPts[TM],MATCH(TableTERanks[[#This Row],[RK]],TableTECalcPts[RK],0)),"") -> NE | Y39: =IFERROR(INDEX(TableTECalcPts[BYE],MATCH(TableTERanks[[#This Row],[RK]],TableTECalcPts[RK],0)),"") -> 11 | Z39: =IFERROR(INDEX(TableTECalcPts[Custom],MATCH(TableTERanks[[#This Row],[RK]],TableTECalcPts[RK],0)),"") -> 50.38664 | AA39: =IF(VLOOKUP(TableTERanks[[#This Row],[Player]],'Ranks w Proj'!$AR:$AZ,9,FALSE)<0,0,VLOOKUP(TableTERanks[[#This Row],[Player]],'Ranks w Proj'!$AR:$AZ,9,FALSE)) -> 0
